// Summary
// Inside the promise, the catch() method will catch the error caused by the throw statement and reject().
// If an error occurs and you donâ€™t have the catch() method, the JavaScript engine issues a runtime error and stops the program.